django.utils.autoreload INFO 2023-01-28 14:50:48,817 autoreload 65791 8097178880 Watching for file changes with StatReloader
django.utils.autoreload INFO 2023-01-28 14:51:28,942 autoreload 65791 8097178880 /Users/nathannoble/django/django_projects/rent_app/rent_app/settings.py changed, reloading.
asyncio DEBUG 2023-01-28 14:51:28,943 selector_events 65791 8097178880 Using selector: KqueueSelector
django.utils.autoreload INFO 2023-01-28 14:51:29,321 autoreload 65855 8097178880 Watching for file changes with StatReloader
django.utils.autoreload INFO 2023-01-28 14:51:58,020 autoreload 65855 8097178880 /Users/nathannoble/django/django_projects/rent_app/rent_app/settings.py changed, reloading.
asyncio DEBUG 2023-01-28 14:51:58,023 selector_events 65855 8097178880 Using selector: KqueueSelector
django.utils.autoreload INFO 2023-01-28 14:51:58,401 autoreload 65875 8097178880 Watching for file changes with StatReloader
django.request ERROR 2023-02-04 19:04:01,138 log 65875 6215217152 Internal Server Error: /admin/login/
Traceback (most recent call last):
  File "/Library/Frameworks/Python.framework/Versions/3.9/lib/python3.9/site-packages/django/db/backends/utils.py", line 84, in _execute
    return self.cursor.execute(sql, params)
  File "/Library/Frameworks/Python.framework/Versions/3.9/lib/python3.9/site-packages/django/db/backends/mysql/base.py", line 73, in execute
    return self.cursor.execute(query, args)
  File "/Library/Frameworks/Python.framework/Versions/3.9/lib/python3.9/site-packages/MySQLdb/cursors.py", line 206, in execute
    res = self._query(query)
  File "/Library/Frameworks/Python.framework/Versions/3.9/lib/python3.9/site-packages/MySQLdb/cursors.py", line 319, in _query
    db.query(q)
  File "/Library/Frameworks/Python.framework/Versions/3.9/lib/python3.9/site-packages/MySQLdb/connections.py", line 254, in query
    _mysql.connection.query(self, query)
MySQLdb._exceptions.ProgrammingError: (1146, "Table 'rent_app.auth_user' doesn't exist")

The above exception was the direct cause of the following exception:

Traceback (most recent call last):
  File "/Library/Frameworks/Python.framework/Versions/3.9/lib/python3.9/site-packages/django/core/handlers/exception.py", line 47, in inner
    response = get_response(request)
  File "/Library/Frameworks/Python.framework/Versions/3.9/lib/python3.9/site-packages/django/core/handlers/base.py", line 181, in _get_response
    response = wrapped_callback(request, *callback_args, **callback_kwargs)
  File "/Library/Frameworks/Python.framework/Versions/3.9/lib/python3.9/site-packages/django/views/decorators/cache.py", line 44, in _wrapped_view_func
    response = view_func(request, *args, **kwargs)
  File "/Library/Frameworks/Python.framework/Versions/3.9/lib/python3.9/site-packages/django/contrib/admin/sites.py", line 414, in login
    return LoginView.as_view(**defaults)(request)
  File "/Library/Frameworks/Python.framework/Versions/3.9/lib/python3.9/site-packages/django/views/generic/base.py", line 70, in view
    return self.dispatch(request, *args, **kwargs)
  File "/Library/Frameworks/Python.framework/Versions/3.9/lib/python3.9/site-packages/django/utils/decorators.py", line 43, in _wrapper
    return bound_method(*args, **kwargs)
  File "/Library/Frameworks/Python.framework/Versions/3.9/lib/python3.9/site-packages/django/views/decorators/debug.py", line 89, in sensitive_post_parameters_wrapper
    return view(request, *args, **kwargs)
  File "/Library/Frameworks/Python.framework/Versions/3.9/lib/python3.9/site-packages/django/utils/decorators.py", line 43, in _wrapper
    return bound_method(*args, **kwargs)
  File "/Library/Frameworks/Python.framework/Versions/3.9/lib/python3.9/site-packages/django/utils/decorators.py", line 130, in _wrapped_view
    response = view_func(request, *args, **kwargs)
  File "/Library/Frameworks/Python.framework/Versions/3.9/lib/python3.9/site-packages/django/utils/decorators.py", line 43, in _wrapper
    return bound_method(*args, **kwargs)
  File "/Library/Frameworks/Python.framework/Versions/3.9/lib/python3.9/site-packages/django/views/decorators/cache.py", line 44, in _wrapped_view_func
    response = view_func(request, *args, **kwargs)
  File "/Library/Frameworks/Python.framework/Versions/3.9/lib/python3.9/site-packages/django/contrib/auth/views.py", line 63, in dispatch
    return super().dispatch(request, *args, **kwargs)
  File "/Library/Frameworks/Python.framework/Versions/3.9/lib/python3.9/site-packages/django/views/generic/base.py", line 98, in dispatch
    return handler(request, *args, **kwargs)
  File "/Library/Frameworks/Python.framework/Versions/3.9/lib/python3.9/site-packages/django/views/generic/edit.py", line 141, in post
    if form.is_valid():
  File "/Library/Frameworks/Python.framework/Versions/3.9/lib/python3.9/site-packages/django/forms/forms.py", line 175, in is_valid
    return self.is_bound and not self.errors
  File "/Library/Frameworks/Python.framework/Versions/3.9/lib/python3.9/site-packages/django/forms/forms.py", line 170, in errors
    self.full_clean()
  File "/Library/Frameworks/Python.framework/Versions/3.9/lib/python3.9/site-packages/django/forms/forms.py", line 373, in full_clean
    self._clean_form()
  File "/Library/Frameworks/Python.framework/Versions/3.9/lib/python3.9/site-packages/django/forms/forms.py", line 400, in _clean_form
    cleaned_data = self.clean()
  File "/Library/Frameworks/Python.framework/Versions/3.9/lib/python3.9/site-packages/django/contrib/auth/forms.py", line 202, in clean
    self.user_cache = authenticate(self.request, username=username, password=password)
  File "/Library/Frameworks/Python.framework/Versions/3.9/lib/python3.9/site-packages/django/views/decorators/debug.py", line 42, in sensitive_variables_wrapper
    return func(*func_args, **func_kwargs)
  File "/Library/Frameworks/Python.framework/Versions/3.9/lib/python3.9/site-packages/django/contrib/auth/__init__.py", line 76, in authenticate
    user = backend.authenticate(request, **credentials)
  File "/Library/Frameworks/Python.framework/Versions/3.9/lib/python3.9/site-packages/django/contrib/auth/backends.py", line 42, in authenticate
    user = UserModel._default_manager.get_by_natural_key(username)
  File "/Library/Frameworks/Python.framework/Versions/3.9/lib/python3.9/site-packages/django/contrib/auth/base_user.py", line 45, in get_by_natural_key
    return self.get(**{self.model.USERNAME_FIELD: username})
  File "/Library/Frameworks/Python.framework/Versions/3.9/lib/python3.9/site-packages/django/db/models/manager.py", line 85, in manager_method
    return getattr(self.get_queryset(), name)(*args, **kwargs)
  File "/Library/Frameworks/Python.framework/Versions/3.9/lib/python3.9/site-packages/django/db/models/query.py", line 431, in get
    num = len(clone)
  File "/Library/Frameworks/Python.framework/Versions/3.9/lib/python3.9/site-packages/django/db/models/query.py", line 262, in __len__
    self._fetch_all()
  File "/Library/Frameworks/Python.framework/Versions/3.9/lib/python3.9/site-packages/django/db/models/query.py", line 1324, in _fetch_all
    self._result_cache = list(self._iterable_class(self))
  File "/Library/Frameworks/Python.framework/Versions/3.9/lib/python3.9/site-packages/django/db/models/query.py", line 51, in __iter__
    results = compiler.execute_sql(chunked_fetch=self.chunked_fetch, chunk_size=self.chunk_size)
  File "/Library/Frameworks/Python.framework/Versions/3.9/lib/python3.9/site-packages/django/db/models/sql/compiler.py", line 1169, in execute_sql
    cursor.execute(sql, params)
  File "/Library/Frameworks/Python.framework/Versions/3.9/lib/python3.9/site-packages/django/db/backends/utils.py", line 98, in execute
    return super().execute(sql, params)
  File "/Library/Frameworks/Python.framework/Versions/3.9/lib/python3.9/site-packages/django/db/backends/utils.py", line 66, in execute
    return self._execute_with_wrappers(sql, params, many=False, executor=self._execute)
  File "/Library/Frameworks/Python.framework/Versions/3.9/lib/python3.9/site-packages/django/db/backends/utils.py", line 75, in _execute_with_wrappers
    return executor(sql, params, many, context)
  File "/Library/Frameworks/Python.framework/Versions/3.9/lib/python3.9/site-packages/django/db/backends/utils.py", line 84, in _execute
    return self.cursor.execute(sql, params)
  File "/Library/Frameworks/Python.framework/Versions/3.9/lib/python3.9/site-packages/django/db/utils.py", line 90, in __exit__
    raise dj_exc_value.with_traceback(traceback) from exc_value
  File "/Library/Frameworks/Python.framework/Versions/3.9/lib/python3.9/site-packages/django/db/backends/utils.py", line 84, in _execute
    return self.cursor.execute(sql, params)
  File "/Library/Frameworks/Python.framework/Versions/3.9/lib/python3.9/site-packages/django/db/backends/mysql/base.py", line 73, in execute
    return self.cursor.execute(query, args)
  File "/Library/Frameworks/Python.framework/Versions/3.9/lib/python3.9/site-packages/MySQLdb/cursors.py", line 206, in execute
    res = self._query(query)
  File "/Library/Frameworks/Python.framework/Versions/3.9/lib/python3.9/site-packages/MySQLdb/cursors.py", line 319, in _query
    db.query(q)
  File "/Library/Frameworks/Python.framework/Versions/3.9/lib/python3.9/site-packages/MySQLdb/connections.py", line 254, in query
    _mysql.connection.query(self, query)
django.db.utils.ProgrammingError: (1146, "Table 'rent_app.auth_user' doesn't exist")
asyncio DEBUG 2023-02-04 19:25:55,884 selector_events 97267 8097178880 Using selector: KqueueSelector
django.utils.autoreload INFO 2023-02-04 19:32:06,281 autoreload 65875 8097178880 /Users/nathannoble/django/django_projects/rent_app/rent_app/urls.py changed, reloading.
asyncio DEBUG 2023-02-04 19:32:06,285 selector_events 65875 8097178880 Using selector: KqueueSelector
django.utils.autoreload INFO 2023-02-04 19:32:06,727 autoreload 97546 8097178880 Watching for file changes with StatReloader
django.request WARNING 2023-02-04 19:32:52,475 log 97546 6136557568 Not Found: /
django.request WARNING 2023-02-04 19:32:55,698 log 97546 6136557568 Not Found: /
django.utils.autoreload INFO 2023-02-04 19:34:46,961 autoreload 97546 8097178880 /Users/nathannoble/django/django_projects/rent_app/rent_app/urls.py changed, reloading.
asyncio DEBUG 2023-02-04 19:34:46,964 selector_events 97546 8097178880 Using selector: KqueueSelector
django.utils.autoreload INFO 2023-02-04 19:34:47,328 autoreload 97706 8097178880 Watching for file changes with StatReloader
asyncio DEBUG 2023-02-04 19:42:17,296 selector_events 98005 8097178880 Using selector: KqueueSelector
asyncio DEBUG 2023-02-04 19:46:37,975 selector_events 98138 8097178880 Using selector: KqueueSelector
